{
 "cells": [
  {
   "cell_type": "markdown",
   "id": "1a8dee6c-b1d8-4de5-a240-496ee5bcc528",
   "metadata": {},
   "source": [
    "# Assignment 6"
   ]
  },
  {
   "cell_type": "markdown",
   "id": "0c9c1581-a9e9-47d8-b42b-fb63a941fa3d",
   "metadata": {},
   "source": [
    "**Q1. Describe three applications for exception processing.**"
   ]
  },
  {
   "cell_type": "markdown",
   "id": "b597b331-2bdc-487a-8582-3bae582f2f62",
   "metadata": {},
   "source": [
    "Exception processing is a powerful mechanism in programming languages like Python that allows you to handle and manage exceptional situations that may occur during the execution of a program. Here are three common applications for exception processing:\n",
    "1. Error Handling: Exception processing is widely used for error handling in software development. It allows you to catch and handle various types of errors, exceptions, and exceptional conditions that may occur during the execution of code. By using try-except blocks, you can gracefully handle errors and prevent them from causing the program to crash or produce incorrect results. Exception handling enables you to provide meaningful error messages, log errors for debugging purposes, and take appropriate actions to recover from errors.\n",
    "2. Input Validation: Exception processing is often employed for input validation and ensuring data integrity. When working with user inputs or external data sources, you can use exception handling to validate and sanitize the input. For example, you can catch exceptions related to invalid data formats, out-of-range values, or missing required fields. By handling these exceptions, you can provide feedback to the user, prompt for valid inputs, or perform alternative actions to handle the invalid data.\n",
    "3. Resource Management: Exception processing is crucial for managing resources, such as files, network connections, or database connections. When working with external resources, exceptions can occur during operations like opening or closing files, establishing or terminating network connections, or executing database queries. By utilizing exception handling techniques, you can ensure proper resource cleanup and release, even in the presence of errors or exceptions. For example, you can use the try-finally block to guarantee the release of acquired resources, regardless of whether an exception occurred or not.\n",
    "Overall, exception processing plays a vital role in maintaining the reliability, stability, and robustness of software systems. It helps handle errors gracefully, validates input, and ensures proper resource management, resulting in more resilient and user-friendly applications."
   ]
  },
  {
   "cell_type": "markdown",
   "id": "014ff83d-fb66-4133-b2dd-1207955ad643",
   "metadata": {},
   "source": [
    "**Q2. What happens if you don't do something extra to treat an exception?**"
   ]
  },
  {
   "cell_type": "markdown",
   "id": "5ce1a9e1-e9c2-4a2b-88bc-6a536cd1dc93",
   "metadata": {},
   "source": [
    "If you don't handle or treat an exception in your code, it will propagate up the call stack until it reaches an appropriate exception handler or, if not caught, it will result in the program terminating and displaying an error message.\n",
    "When an exception is not handled, the following sequence of events typically occurs:\n",
    "1. Exception Propagation: If an exception occurs within a try block and is not caught by an except block that can handle it, the exception propagates up the call stack, searching for an exception handler. This means that the exception moves up through the layers of function calls until it finds a suitable exception handler or reaches the top-level of the program.\n",
    "2. Stack Unwinding: As the exception propagates up the call stack, the program starts unwinding the call stack, which means that the execution of the current function is interrupted and the control is transferred back to the calling function. This continues until an appropriate exception handler is found.\n",
    "3. Program Termination: If the exception reaches the top-level of the program without being caught by any exception handler, the default behavior is for the program to terminate. In this case, an error message is usually displayed, indicating the type of exception that occurred and the traceback information, which shows the sequence of function calls leading to the exception.\n",
    "By not treating or handling an exception, the program loses the opportunity to handle errors in a controlled manner. It can lead to unexpected behavior, crashes, or incorrect results. Proper exception handling allows you to gracefully handle exceptional situations, provide informative error messages, take appropriate actions, and maintain the stability and integrity of your program."
   ]
  },
  {
   "cell_type": "markdown",
   "id": "53989325-63bb-45a2-8520-5aa83710d27f",
   "metadata": {},
   "source": [
    "**Q3. What are your options for recovering from an exception in your script?**"
   ]
  },
  {
   "cell_type": "markdown",
   "id": "ec7b620e-9427-4388-802d-e1017c8295c3",
   "metadata": {},
   "source": [
    "When an exception occurs in a script, you have several options for recovering from it and handling the exceptional situation. Here are some common approaches:\n",
    "1. Exception Handling: You can use the `try-except` statement to catch and handle specific exceptions. By wrapping the code that may raise an exception within a `try` block, you can specify one or more `except` blocks to handle specific exceptions. Inside the `except` block, you can provide appropriate error handling logic, perform necessary cleanup, log the error, or take alternative actions to recover from the exception.\n",
    "2. Error Reporting and Logging: Even if you can't recover from an exception, it's important to report the error and log relevant information for debugging and troubleshooting. You can use functions like `print()` or logging libraries to display error messages or write them to a log file. This information can help you identify the cause of the exception and provide useful feedback to users or developers.\n",
    "3. Graceful Degradation: In some cases, it may be possible to gracefully degrade the functionality of your script when an exception occurs. Instead of terminating the script entirely, you can handle the exception, continue with the remaining code execution, and provide alternative or limited functionality. This approach allows the script to keep running and provides users with a partial or degraded experience instead of a complete failure.\n",
    "4. Retry Mechanism: If the exception is transient or occurs due to temporary conditions, you can implement a retry mechanism. This involves catching the exception, waiting for a certain period, and then attempting to execute the code again. By using a loop or recursion, you can repeat the operation until it succeeds or until a maximum number of retries is reached.\n",
    "5. Graceful Termination: In some cases, the best course of action is to gracefully terminate the script when an exception occurs. This involves catching the exception, performing any necessary cleanup operations, and then exiting the script with an appropriate exit code. Graceful termination ensures that resources are properly released and the script ends in a controlled manner.\n",
    "The choice of recovery options depends on the specific situation, the nature of the exception, and the requirements of your script. It's important to consider the potential impact of the exception, the possibility of recovery, and the desired behavior in exceptional circumstances."
   ]
  },
  {
   "cell_type": "markdown",
   "id": "40be647e-46fe-4157-b8d9-59d64b39bb82",
   "metadata": {},
   "source": [
    "**Q4. Describe two methods for triggering exceptions in your script.**"
   ]
  },
  {
   "cell_type": "markdown",
   "id": "05a9b35a-cfaf-4ae3-8ee6-fd9360755991",
   "metadata": {},
   "source": [
    "In Python, you can trigger exceptions intentionally in your script using various methods to handle exceptional situations. Here are two common methods for triggering exceptions:\n",
    "1. Using the `raise` Statement: The `raise` statement allows you to explicitly raise an exception in your script. You can raise a specific exception type by creating an instance of the exception class and passing it as an argument to the `raise` statement. This method is useful when you want to indicate that a particular condition or situation warrants an exception. For example:"
   ]
  },
  {
   "cell_type": "code",
   "execution_count": 1,
   "id": "79ca2436-242d-4916-8ba7-b8d918fdb599",
   "metadata": {},
   "outputs": [
    {
     "name": "stdout",
     "output_type": "stream",
     "text": [
      "Exception: Divisor cannot be zero\n"
     ]
    }
   ],
   "source": [
    "\n",
    "def divide(a, b):\n",
    "    if b == 0:\n",
    "        raise ValueError(\"Divisor cannot be zero\")\n",
    "    return a / b\n",
    "try:\n",
    "    result = divide(10, 0)\n",
    "except ValueError as e:\n",
    "    print(\"Exception:\", str(e))\n"
   ]
  },
  {
   "cell_type": "markdown",
   "id": "3be5d426-8a8f-4f1f-bb31-680ee119f9f3",
   "metadata": {},
   "source": [
    "In the above example, if the divisor (`b`) is zero, a `ValueError` exception is raised using the `raise` statement. This allows you to handle the exceptional situation in the `except` block and provide appropriate feedback or take alternative actions.\n",
    "2. Invoking Built-in Exceptions: Python provides a range of built-in exceptions that can be raised to handle specific exceptional conditions. You can directly raise these exceptions in your script to indicate and handle different types of errors or exceptional situations. Some common built-in exceptions include `ValueError`, `TypeError`, `FileNotFoundError`, and `IndexError`, among others. For example:"
   ]
  },
  {
   "cell_type": "code",
   "execution_count": 2,
   "id": "f5152c16-7ddf-4b89-89ab-375564e4dfcc",
   "metadata": {},
   "outputs": [
    {
     "name": "stdout",
     "output_type": "stream",
     "text": [
      "Exception: Index out of range\n"
     ]
    }
   ],
   "source": [
    "\n",
    "def find_element(lst, index):\n",
    "    if index >= len(lst):\n",
    "        raise IndexError(\"Index out of range\")\n",
    "    return lst[index]\n",
    "try:\n",
    "    my_list = [1, 2, 3]\n",
    "    result = find_element(my_list, 5)\n",
    "except IndexError as e:\n",
    "    print(\"Exception:\", str(e))"
   ]
  },
  {
   "cell_type": "markdown",
   "id": "b592494f-ed2b-4caa-a71b-779faf78839d",
   "metadata": {},
   "source": [
    "**Q5. Identify two methods for specifying actions to be executed at termination time, regardless of whether or not an exception exists.**"
   ]
  },
  {
   "cell_type": "markdown",
   "id": "de1c280e-ba99-4468-b0fb-ac966820175d",
   "metadata": {},
   "source": [
    "In Python, you can use the `finally` block and the `atexit` module to specify actions to be executed at termination time, regardless of whether or not an exception exists. Here's an explanation of both methods:\n",
    "1. The `finally` Block: The `finally` block is used in conjunction with the `try` and `except` blocks to define a set of statements that are guaranteed to be executed, regardless of whether an exception occurs or not. The code within the `finally` block is executed after the `try` block completes, regardless of whether an exception is raised or caught. This block is useful for releasing resources, closing files, or performing any necessary cleanup operations. Here's an example:"
   ]
  },
  {
   "cell_type": "code",
   "execution_count": 5,
   "id": "6414a690-9af6-45a9-bd15-0a4b88ed144d",
   "metadata": {},
   "outputs": [],
   "source": [
    "file = None\n",
    "try:\n",
    "    file = open(\"data.txt\", \"r\")\n",
    "    # Perform some operations with the file\n",
    "except IOError as e:\n",
    "    print(\"Error:\", str(e))\n",
    "finally:\n",
    "    if file is not None:\n",
    "        file.close()"
   ]
  },
  {
   "cell_type": "markdown",
   "id": "3bd06bb8-0f2c-4798-94eb-001b497be86a",
   "metadata": {},
   "source": [
    "In this example, the `finally` block ensures that the file is closed even if an exception occurs during the file operations. The `file.close()` statement is executed regardless of whether an exception was raised or not.\n",
    "2. The `atexit` Module: The `atexit` module allows you to register functions to be executed at program termination, regardless of whether an exception occurs or not. You can use the `atexit.register()` function to register a function to be called when the program exits. This is useful for performing cleanup tasks or final actions before the program terminates. Here's an example:"
   ]
  },
  {
   "cell_type": "code",
   "execution_count": 6,
   "id": "7947b22b-d4c4-4a1d-adfc-644b512ff50f",
   "metadata": {},
   "outputs": [
    {
     "data": {
      "text/plain": [
       "<function __main__.cleanup()>"
      ]
     },
     "execution_count": 6,
     "metadata": {},
     "output_type": "execute_result"
    }
   ],
   "source": [
    "import atexit\n",
    "def cleanup():\n",
    "    # Perform cleanup actions\n",
    "    print(\"Performing cleanup actions\")\n",
    "atexit.register(cleanup)\n"
   ]
  },
  {
   "cell_type": "markdown",
   "id": "ad4148dc-0835-425c-8b73-7ba276897b58",
   "metadata": {},
   "source": [
    "In this example, the `cleanup()` function is registered using `atexit.register()`. When the program exits, either normally or due to an unhandled exception, the `cleanup()` function will be automatically called.\n",
    "Using the `finally` block and the `atexit` module, you can ensure that specific actions are executed at termination time, regardless of the presence of exceptions. These mechanisms allow you to handle cleanup operations, release resources, and perform necessary final actions to maintain the integrity of your program."
   ]
  },
  {
   "cell_type": "markdown",
   "id": "597b9044-13bf-4e3d-924d-2f6ace3cc6a1",
   "metadata": {},
   "source": []
  }
 ],
 "metadata": {
  "kernelspec": {
   "display_name": "Python 3 (ipykernel)",
   "language": "python",
   "name": "python3"
  },
  "language_info": {
   "codemirror_mode": {
    "name": "ipython",
    "version": 3
   },
   "file_extension": ".py",
   "mimetype": "text/x-python",
   "name": "python",
   "nbconvert_exporter": "python",
   "pygments_lexer": "ipython3",
   "version": "3.10.6"
  }
 },
 "nbformat": 4,
 "nbformat_minor": 5
}
